Workbook

Sheet README
A1: Market Research & Data Analyst Assessment - Workbook
A2: Prepared by Manoj Kumar | Research date: 8 October 2026 | All prices in AUD
A4: Purpose | B4: Supporting calculations and research tables for the 15-question assessment. The written answers are in the companion Word document.
A5: AI disclosure | B5: This submission was prepared with AI assistance (Claude), which the candidate confirms the interviewer/company permitted for this assessment.
A6: How to read | B6: Blue text on yellow = inputs/assumptions you can change. Black = formulas. Green fill = key result.
A7: Q1_Profit | B7: Profit $ and margin % per product, highest-margin product, priority recommendation (Q1).
A8: Q2_Functions | B8: Live examples of SUM, AVERAGE, IF, COUNTIF, VLOOKUP and INDEX/MATCH on small sample data. XLOOKUP is shown as typed text only (see note on that sheet).
A9: Q4_Competitors | B9: 15 verified product records (3 each from Kogan, Big W, Kmart, Temple & Webster, Bunnings) for ONE category: office chairs.
A10: Q4_Summary | B10: Per-competitor price statistics, discount behaviour and rating signals, calculated from Q4_Competitors.
A11: Q5_Opportunities | B11: Three product opportunities, verified competitor prices, Google Trends reading, and a break-even buying-cost calculator.
A12: Q6_Profitability | B12: Profit and margin on the $149.95 competitor-price scenario, with scenarios and break-even price.
A13: Q8_Sales | B13: Traffic, orders and conversion analysis for Jan-Apr.
A14: Q9_Funnel | B14: Four funnel conversion rates and the weakest stage.
A15: Sources | B15: Source register: every external fact used, with URL and access date.
... A17: Method note | B17: Prices were read from each retailer's own product or search page on 8 Oct 2026 (Chrome). Prices change often. Where something could not be verified (for example delivery cost, which depends on postcode) the cell says so rather than guessing.

Sheet Q1_Profit
A1: Q1 - Basic Excel: profit and margin
A2: Source: product data supplied in the assessment document
A4: Product | B4: Cost Price | C4: Selling Price | D4: Profit ($) | E4: Profit Margin % | F4: Markup on cost % | G4: Margin rank | H4: $ profit rank
A5: Office Chair | B5: 120 | C5: 179 | D5: =C5-B5 -> 59 | E5: =D5/C5 -> 0.32960894 | F5: =D5/B5 -> 0.49166667 | G5: =RANK(E5,$E$5:$E$9) -> 4 | H5: =RANK(D5,$D$5:$D$9) -> 2
A6: Storage Cabinet | B6: 85 | C6: 129 | D6: =C6-B6 -> 44 | E6: =D6/C6 -> 0.34108527 | F6: =D6/B6 -> 0.51764706 | G6: =RANK(E6,$E$5:$E$9) -> 3 | H6: =RANK(D6,$D$5:$D$9) -> 3
A7: Garden Table | B7: 150 | C7: 219 | D7: =C7-B7 -> 69 | E7: =D7/C7 -> 0.31506849 | F7: =D7/B7 -> 0.46 | G7: =RANK(E7,$E$5:$E$9) -> 5 | H7: =RANK(D7,$D$5:$D$9) -> 1
A8: Tool Box | B8: 45 | C8: 69 | D8: =C8-B8 -> 24 | E8: =D8/C8 -> 0.34782609 | F8: =D8/B8 -> 0.53333333 | G8: =RANK(E8,$E$5:$E$9) -> 2 | H8: =RANK(D8,$D$5:$D$9) -> 5
A9: Bedside Table | B9: 60 | C9: 99 | D9: =C9-B9 -> 39 | E9: =D9/C9 -> 0.39393939 | F9: =D9/B9 -> 0.65 | G9: =RANK(E9,$E$5:$E$9) -> 1 | H9: =RANK(D9,$D$5:$D$9) -> 4
A11: Highest profit margin % | B11: =INDEX(A5:A9,MATCH(MAX(E5:E9),E5:E9,0)) -> Bedside Table | C11: =MAX(E5:E9) -> 0.39393939
A12: Highest $ profit per unit | B12: =INDEX(A5:A9,MATCH(MAX(D5:D9),D5:D9,0)) -> Garden Table | C12: =MAX(D5:D9) -> 69
A13: Lowest profit margin % | B13: =INDEX(A5:A9,MATCH(MIN(E5:E9),E5:E9,0)) -> Garden Table | C13: =MIN(E5:E9) -> 0.31506849
A15: Margin % = profit / selling price. Markup % = profit / cost. Both are before shipping, payment fees and marketing.
A16: Recommendation: prioritise Bedside Table first (best margin, and only $60 of cash tied up per unit); Garden Table second for the largest $ profit per sale. See the written answer for the reasoning and caveats.

Sheet Q2_Functions
A1: Q2 - Excel functions: working examples
A2: Sample order data below is made up for teaching purposes (not real sales). Product prices link to Q1.
A4: Order ID | B4: Product | C4: Qty | D4: Revenue ($) | E4: Region
A5: 1001 | B5: Office Chair | C5: 2 | D5: 358 | E5: NSW
A6: 1002 | B6: Tool Box | C6: 5 | D6: 345 | E6: VIC
A7: 1003 | B7: Bedside Table | C7: 1 | D7: 99 | E7: NSW
A8: 1004 | B8: Garden Table | C8: 1 | D8: 219 | E8: QLD
A9: 1005 | B9: Office Chair | C9: 1 | D9: 179 | E9: VIC
A10: 1006 | B10: Storage Cabinet | C10: 3 | D10: 387 | E10: NSW
A11: 1007 | B11: Bedside Table | C11: 4 | D11: 396 | E11: VIC
A12: 1008 | B12: Tool Box | C12: 2 | D12: 138 | E12: NSW
A15: Function | B15: Purpose | C15: Formula as typed | D15: Result (live) | E15: What it tells us
A16: SUM | B16: Add numbers | C16: =SUM(D5:D12) | D16: =SUM(D5:D12) -> 2121 | E16: Total revenue across all orders
A17: AVERAGE | B17: Mean of a range | C17: =AVERAGE(D5:D12) | D17: =AVERAGE(D5:D12) -> 265.125 | E17: Average order value
A18: IF | B18: Return one value if a test is true, another if not | C18: =IF(Q1_Profit!E9>=0.35,"Keep - strong margin","Review pricing") | D18: =IF(Q1_Profit!E9>=0.35,"Keep - strong margin","Review pricing") -> Keep - strong margin | E18: Flags Bedside Table margin (from Q1) against a 35% target
A19: COUNTIF | B19: Count cells that meet one condition | C19: =COUNTIF(E5:E12,"NSW") | D19: =COUNTIF(E5:E12,"NSW") -> 4 | E19: Number of NSW orders
A20: VLOOKUP | B20: Find a value in the first column of a table and return a column to the right | C20: =VLOOKUP(B6,Q1_Profit!$A$5:$C$9,3,FALSE) | D20: =VLOOKUP(B6,Q1_Profit!$A$5:$C$9,3,FALSE()) -> 69 | E20: Selling price of the product in order 1002 (Tool Box)
A21: INDEX + MATCH | B21: Same job as VLOOKUP but can look left and survives inserted columns | C21: =INDEX(Q1_Profit!$B$5:$B$9,MATCH(B8,Q1_Profit!$A$5:$A$9,0)) | D21: =INDEX(Q1_Profit!$B$5:$B$9,MATCH(B8,Q1_Profit!$A$5:$A$9,0)) -> 150 | E21: Cost price of the product in order 1004 (Garden Table) - the cost column sits LEFT of the lookup column
A22: XLOOKUP | B22: Modern replacement for VLOOKUP/HLOOKUP: looks in any direction, exact match by default, has a built-in 'not found' argument | C22: =XLOOKUP(B6,Q1_Profit!$A$5:$A$9,Q1_Profit!$C$5:$C$9,"Not found") | D22: Typed text only | E22: Would return 69 (Tool Box selling price). Not evaluated here so the file also opens correctly in older Excel and LibreOffice; INDEX/MATCH above gives the same answer.
A24: Pivot Table (bonus): used when you need to summarise a long table by category, region or month without writing formulas, for example total revenue by product and region from thousands of order rows. See written answer.

Sheet Q4_Competitors
A1: Q4 - Competitor research: OFFICE CHAIRS (15 verified records)
A2: Category chosen because all five retailers sell it online (checked 8 Oct 2026). 'Selling price' = price any shopper pays (Kogan: non-member price). Member price shown separately.
A4: ID | B4: Competitor | C4: Product / category | D4: Product name | E4: Brand / seller | F4: Chair type | G4: Selling price ($) | H4: Kogan member price ($) | I4: Original / RRP ($) | J4: Discount ($) | K4: Discount % | L4: Shipping information | M4: Rating (out of 5) | N4: No. of reviews | O4: Product URL | P4: Observation | Q4: Date accessed | R4: Rating x reviews (helper)
A5: KM1 | B5: Kmart | C5: Home office furniture / Office chairs | D5: Boucle Home Office Chair | E5: Kmart (own brand) | F5: Upholstered (boucle) | G5: 149 | H5: n/a | I5: none shown | J5: =IF(ISNUMBER(I5),I5-G5,0) -> 0 | K5: =IF(ISNUMBER(I5),J5/I5,0) -> 0 | L5: Fulfilled & delivered by Kmart (online only). Search page shows 'Free delivery on eligible items'; exact cost/eligibility for a postcode not verified. | M5: 4.7 | N5: 12 | O5: https://www.kmart.com.au/product/boucle-home-office-chair-43228386/ | P5: Fashion-led home chair: gas lift, swivel, 100kg limit; no lumbar or tilt features listed. Highest rating of the Kmart set but only 12 reviews. | Q5: 46303 | R5: =IF(ISNUMBER(M5),M5*N5,0) -> 56.4
A6: KM2 | B6: Kmart | C6: Home office furniture / Office chairs | D6: Sky Office Chair | E6: Kmart (own brand) | F6: Faux leather (PU) | G6: 149 | H6: n/a | I6: none shown | J6: =IF(ISNUMBER(I6),I6-G6,0) -> 0 | K6: =IF(ISNUMBER(I6),J6/I6,0) -> 0 | L6: Fulfilled & delivered by Kmart (online only). Search page shows 'Free delivery on eligible items'; exact cost/eligibility for a postcode not verified. | M6: no rating | N6: 0 | O6: https://www.kmart.com.au/product/sky-office-chair-43682737/ | P6: Cream PU, gas lift + manual seat-depth adjustment, 100kg. Shows a 'Bestseller' badge in search results despite 0 reviews, so the badge is not a review-based signal. | Q6: 46303 | R6: =IF(ISNUMBER(M6),M6*N6,0) -> 0
A7: KM3 | B7: Kmart | C7: Home office furniture / Office chairs | D7: Alfordson Mesh Office Chair Executive Seat Tilt Gaming Racing Computer - Grey | E7: Alfordson / Aussie Union Group (marketplace) | F7: Mesh ergonomic | G7: 79.85 | H7: n/a | I7: none shown | J7: =IF(ISNUMBER(I7),I7-G7,0) -> 0 | K7: =IF(ISNUMBER(I7),J7/I7,0) -> 0 | L7: Marketplace: sold & shipped by Aussie Union Group. Delivery cost for a postcode not verified. | M7: 5 | N7: 1 | O7: https://www.kmart.com.au/product/alfordson-mesh-office-chair-executive-seat-tilt-gaming-racing-computer-grey-110049597/ | P7: Headrest, lumbar support, tilt, 180kg limit, 1-yr warranty. Nearly half the price of Kmart's own chairs but only one review. Kmart shows no 'was' prices on these items. | Q7: 46303 | R7: =IF(ISNUMBER(M7),M7*N7,0) -> 5
A8: BN1 | B8: Bunnings | C8: Home office furniture / Office chairs | D8: ALFORDSON Mesh Office Chair Dark Grey | E8: Alfordson / Aussie Union Group (marketplace) | F8: Mesh ergonomic | G8: 59.85 | H8: n/a | I8: none shown | J8: =IF(ISNUMBER(I8),I8-G8,0) -> 0 | K8: =IF(ISNUMBER(I8),J8/I8,0) -> 0 | L8: Marketplace, online only; sold & delivered by seller (not available for Click & Collect). Delivery estimate requires a postcode - not verified. | M8: 2.9 | N8: 27 | O8: https://www.bunnings.com.au/alfordson-mesh-office-chair-dark-grey_p0508818 | P8: Lowest-priced Bunnings record; 27 reviews at 2.9 stars suggests quality concerns at this price. | Q8: 46303 | R8: =IF(ISNUMBER(M8),M8*N8,0) -> 78.3
A9: BN2 | B9: Bunnings | C9: Home office furniture / Office chairs | D9: ALFORDSON Office Chair White | E9: Alfordson / Aussie Union Group (marketplace) | F9: Not captured | G9: 109.85 | H9: n/a | I9: none shown | J9: =IF(ISNUMBER(I9),I9-G9,0) -> 0 | K9: =IF(ISNUMBER(I9),J9/I9,0) -> 0 | L9: Marketplace, online only; sold & delivered by seller (not available for Click & Collect). Delivery estimate requires a postcode - not verified. | M9: 3.9 | N9: 39 | O9: https://www.bunnings.com.au/alfordson-office-chair-white_p0477986 | P9: Most-reviewed of the three (39). Search shows 978 office-chair results, almost all marketplace listings. | Q9: 46303 | R9: =IF(ISNUMBER(M9),M9*N9,0) -> 152.1
A10: BN3 | B10: Bunnings | C10: Home office furniture / Office chairs | D10: Artiss Black PU Leather Executive Office Chair | E10: Artiss / Arcadian Living (marketplace) | F10: Faux leather (PU) executive | G10: 135.66 | H10: n/a | I10: none shown | J10: =IF(ISNUMBER(I10),I10-G10,0) -> 0 | K10: =IF(ISNUMBER(I10),J10/I10,0) -> 0 | L10: Marketplace, online only; sold & delivered by seller (not available for Click & Collect). Delivery estimate requires a postcode - not verified. | M10: 4.4 | N10: 26 | O10: https://www.bunnings.com.au/artiss-black-pu-leather-executive-office-chair_p0215110 | P10: Best-rated Bunnings record (4.4). A second listing of the same name (p0215116) is $115.77 at 2.9 stars (7 reviews), so near-identical listings can differ by $20. | Q10: 46303 | R10: =IF(ISNUMBER(M10),M10*N10,0) -> 114.4
A11: BW1 | B11: Big W | C11: Home office furniture / Office chairs | D11: 1 ALFORDSON Office Chair (Mesh, Conrad series) | E11: Alfordson / Aussie Union Group (marketplace) | F11: Mesh ergonomic | G11: 24.85 | H11: n/a | I11: 34.85 | J11: =IF(ISNUMBER(I11),I11-G11,0) -> 10 | K11: =IF(ISNUMBER(I11),J11/I11,0) -> 0.28694405 | L11: Marketplace, delivery only, online only; listing shows '+ delivery fee' (amount not verified). Site banner: free delivery on orders $59+ (standard metro) - not confirmed to apply to marketplace items. | M11: 3 | N11: 1 | O11: https://www.bigw.com.au/product/1-alfordson-office-chair/p/9900120141 | P11: Price is unusually low for a chair; shown with 'SAVE $10.00' and 'Lowest price in 14 days'. Original price derived as price + $10 saving. One review only. | Q11: 46303 | R11: =IF(ISNUMBER(M11),M11*N11,0) -> 3
A12: BW2 | B12: Big W | C12: Home office furniture / Office chairs | D12: ALFORDSON Velvet Office Chair for Work Mid Back Grey | E12: Alfordson / Aussie Union Group (marketplace) | F12: Upholstered (velvet) | G12: 114.85 | H12: n/a | I12: 129.85 | J12: =IF(ISNUMBER(I12),I12-G12,0) -> 15 | K12: =IF(ISNUMBER(I12),J12/I12,0) -> 0.11551791 | L12: Marketplace, delivery only, online only; listing shows '+ delivery fee' (amount not verified). Site banner: free delivery on orders $59+ (standard metro) - not confirmed to apply to marketplace items. | M12: 5 | N12: 1 | O12: https://www.bigw.com.au/product/alfordson-velvet-office-chair-for-work-mid-back-grey/p/9900116761 | P12: 'SAVE $15.00' badge. Original price derived as price + $15. Also carries a sponsored tag in search. | Q12: 46303 | R12: =IF(ISNUMBER(M12),M12*N12,0) -> 5
A13: BW3 | B13: Big W | C13: Home office furniture / Office chairs | D13: ALFORDSON Mesh Office Chair Racing Ergonomic Computer Chair All Black | E13: Alfordson / Aussie Union Group (marketplace) | F13: Mesh ergonomic | G13: 64.85 | H13: n/a | I13: none shown | J13: =IF(ISNUMBER(I13),I13-G13,0) -> 0 | K13: =IF(ISNUMBER(I13),J13/I13,0) -> 0 | L13: Marketplace, delivery only, online only; listing shows '+ delivery fee' (amount not verified). Site banner: free delivery on orders $59+ (standard metro) - not confirmed to apply to marketplace items. | M13: no rating | N13: 0 | O13: https://www.bigw.com.au/product/alfordson-mesh-office-chair-racing-ergonomic-computer-chair-all-black/p/9902748573 | P13: No reviews yet. All three Big W records come from the same marketplace seller as the Kmart and Bunnings Alfordson records. | Q13: 46303 | R13: =IF(ISNUMBER(M13),M13*N13,0) -> 0
A14: KG1 | B14: Kogan | C14: Home office furniture / Office chairs | D14: Ergolux Plus Ergonomic Mesh Office Chair with Footrest (Black) | E14: Ergolux (Kogan exclusive brand) | F14: Mesh ergonomic + footrest | G14: 169 | H14: 139 | I14: 349 | J14: =IF(ISNUMBER(I14),I14-G14,0) -> 180 | K14: =IF(ISNUMBER(I14),J14/I14,0) -> 0.51575931 | L14: Product page showed 'Fast Dispatch' only; delivery fee not displayed in captured text. Kogan FIRST membership is offered ($129/yr after free trial). | M14: 4.3 | N14: 128 | O14: https://www.kogan.com/au/buy/ergolux-plus-ergonomic-mesh-office-chair-with-footrest-black-ergolux/ | P14: Highest-reviewed Kogan item. Price is a three-tier structure: member $139, non-member $169, 'SRP' $349. The SRP is a reference price, not proof the chair ever sold at $349. | Q14: 46303 | R14: =IF(ISNUMBER(M14),M14*N14,0) -> 550.4
A15: KG2 | B15: Kogan | C15: Home office furniture / Office chairs | D15: Ergolux Core Ergonomic Foam Office Chair (Black) | E15: Ergolux (Kogan exclusive brand) | F15: Foam ergonomic | G15: 139 | H15: 99.99 | I15: 249 | J15: =IF(ISNUMBER(I15),I15-G15,0) -> 110 | K15: =IF(ISNUMBER(I15),J15/I15,0) -> 0.44176707 | L15: Product page showed 'Fast Dispatch' only; delivery fee not displayed in captured text. Kogan FIRST membership is offered ($129/yr after free trial). | M15: 3.7 | N15: 13 | O15: https://www.kogan.com/au/buy/ergolux-core-ergonomic-foam-office-chair-black-ergolux/ | P15: Entry model in the Ergolux range (Core / Plus / Elite). Member price is $39 below non-member price. | Q15: 46303 | R15: =IF(ISNUMBER(M15),M15*N15,0) -> 48.1
A16: KG3 | B16: Kogan | C16: Home office furniture / Office chairs | D16: Levede Adjustable Armrest Office Mesh Gaming Chair Recliner | E16: Levede / Traderight (marketplace) | F16: Mesh gaming recliner | G16: 83.99 | H16: 75.99 | I16: 167.99 | J16: =IF(ISNUMBER(I16),I16-G16,0) -> 84 | K16: =IF(ISNUMBER(I16),J16/I16,0) -> 0.50002976 | L16: Marketplace seller Traderight: leaves warehouse in 1-2 business days. Delivery fee not displayed in captured text. | M16: no rating | N16: 0 | O16: https://www.kogan.com/au/buy/sel-levede-office-chair-mesh-gaming-executive-tilt-chairs-computer-study-work-seat-of1040-bk/ | P16: 'Don't Pay' reference price $167.99 (a Kogan-displayed comparison price, not verified). No rating shown on the product page. Page notes 2 other offers from $106.74. | Q16: 46303 | R16: =IF(ISNUMBER(M16),M16*N16,0) -> 0
A17: TW1 | B17: Temple & Webster | C17: Home office furniture / Office chairs | D17: Kylian Executive Chair | E17: Living Fusion (T&W brand) | F17: Executive (massage function listed) | G17: 179 | H17: n/a | I17: none shown | J17: =IF(ISNUMBER(I17),I17-G17,0) -> 0 | K17: =IF(ISNUMBER(I17),J17/I17,0) -> 0 | L17: Delivery cost/time is calculated by postcode and was not shown on the product page - not verified. T&W site promo: 15% off with code OCT15 (min spend $149), ends Monday - NOT included in price shown. | M17: 4.5 | N17: 206 | O17: https://www.templeandwebster.com.au/Kylian-Executive-Chair-OIKT1510.html | P17: Review breakdown: 148 five-star, 37 four-star, 11 three-star, 6 two-star, 4 one-star. | Q17: 46303 | R17: =IF(ISNUMBER(M17),M17*N17,0) -> 927
A18: TW2 | B18: Temple & Webster | C18: Home office furniture / Office chairs | D18: Naomi Mesh Office Chair | E18: HoxtonRoom (T&W) | F18: Mesh ergonomic | G18: 99.95 | H18: n/a | I18: none shown | J18: =IF(ISNUMBER(I18),I18-G18,0) -> 0 | K18: =IF(ISNUMBER(I18),J18/I18,0) -> 0 | L18: Delivery cost/time is calculated by postcode and was not shown on the product page - not verified. T&W site promo: 15% off with code OCT15 (min spend $149), ends Monday - NOT included in price shown. | M18: 4.4 | N18: 284 | O18: https://www.templeandwebster.com.au/Naomi-Mesh-Office-Chair-ALFD1293.html | P18: Most-reviewed chair in the whole dataset (284) and mid-priced - the best-evidenced mesh chair here. Adjustable headrest, armrests, lumbar support. | Q18: 46303 | R18: =IF(ISNUMBER(M18),M18*N18,0) -> 1249.6
A19: TW3 | B19: Temple & Webster | C19: Home office furniture / Office chairs | D19: Holly Boucle Office Chair | E19: Temple & Webster (own brand) | F19: Upholstered (boucle) | G19: 219 | H19: n/a | I19: none shown | J19: =IF(ISNUMBER(I19),I19-G19,0) -> 0 | K19: =IF(ISNUMBER(I19),J19/I19,0) -> 0 | L19: Delivery cost/time is calculated by postcode and was not shown on the product page - not verified. T&W site promo: 15% off with code OCT15 (min spend $149), ends Monday - NOT included in price shown. | M19: 4.9 | N19: 183 | O19: https://www.templeandwebster.com.au/Holly-Boucle-Office-Chair-TMPL6117.html | P19: Highest rating in the dataset (4.9 from 183 reviews) and the highest price. Style-led chair; compare with Kmart's $149 boucle chair, not with mesh chairs. | Q19: 46303 | R19: =IF(ISNUMBER(M19),M19*N19,0) -> 896.7
A21: Notes
A22: 1. Comparability: these are NOT identical products. Compare within 'Chair type' (Q4_Summary does this for mesh chairs) rather than across all 15 rows.
A23: 2. Discount % is calculated against the original/RRP shown on the retailer page. For Big W the original is derived (price + 'SAVE $x' badge). Kogan 'SRP' and 'Don't Pay' prices are reference prices and overstate real discounts.
A24: 3. Kogan selling price uses the non-member price so it is comparable with retailers that do not require a membership. Member prices are in column H.
A25: 4. Delivery costs depend on postcode and could not be verified without entering one, so they are not added to prices. Q10 explains how a fair delivered-price comparison would be done.
A26: 5. 'Marketplace' items are sold by third-party sellers; Alfordson / Aussie Union Group appears on Kmart, Bunnings and Big W.
A27: 6. Rating 'no rating' means the product page showed none (usually 0 reviews).

Sheet Q4_Summary
A1: Q4 - Analysis of collected data (all formulas read from Q4_Competitors)
A4: Competitor | B4: No. of products | C4: Lowest price | D4: Median price | E4: Highest price | F4: Average price | G4: Avg rating (simple, rated items) | H4: Total reviews | I4: Items with a 'was' price | J4: Review-weighted rating
A5: Kmart | B5: =COUNTIF(Q4_Competitors!$B$5:$B$19,A5) -> 3 | C5: =MIN(Q4_Competitors!G5:G7) -> 79.85 | D5: =MEDIAN(Q4_Competitors!G5:G7) -> 149 | E5: =MAX(Q4_Competitors!G5:G7) -> 149 | F5: =AVERAGEIF(Q4_Competitors!$B$5:$B$19,A5,Q4_Competitors!$G$5:$G$19) -> 125.95 | G5: =IFERROR(AVERAGEIF(Q4_Competitors!$B$5:$B$19,A5,Q4_Competitors!$M$5:$M$19),"n/a") -> 4.85 | H5: =SUMIF(Q4_Competitors!$B$5:$B$19,A5,Q4_Competitors!$N$5:$N$19) -> 13 | I5: =COUNTIFS(Q4_Competitors!$B$5:$B$19,A5,Q4_Competitors!$K$5:$K$19,">0") -> 0 | J5: =SUMIF(Q4_Competitors!$B$5:$B$19,A5,Q4_Competitors!$R$5:$R$19)/SUMIF(Q4_Competitors!$B$5:$B$19,A5,Q4_Competitors!$N$5:$N$19) -> 4.7230769
A6: Bunnings | B6: =COUNTIF(Q4_Competitors!$B$5:$B$19,A6) -> 3 | C6: =MIN(Q4_Competitors!G8:G10) -> 59.85 | D6: =MEDIAN(Q4_Competitors!G8:G10) -> 109.85 | E6: =MAX(Q4_Competitors!G8:G10) -> 135.66 | F6: =AVERAGEIF(Q4_Competitors!$B$5:$B$19,A6,Q4_Competitors!$G$5:$G$19) -> 101.78667 | G6: =IFERROR(AVERAGEIF(Q4_Competitors!$B$5:$B$19,A6,Q4_Competitors!$M$5:$M$19),"n/a") -> 3.7333333 | H6: =SUMIF(Q4_Competitors!$B$5:$B$19,A6,Q4_Competitors!$N$5:$N$19) -> 92 | I6: =COUNTIFS(Q4_Competitors!$B$5:$B$19,A6,Q4_Competitors!$K$5:$K$19,">0") -> 0 | J6: =SUMIF(Q4_Competitors!$B$5:$B$19,A6,Q4_Competitors!$R$5:$R$19)/SUMIF(Q4_Competitors!$B$5:$B$19,A6,Q4_Competitors!$N$5:$N$19) -> 3.7478261
A7: Big W | B7: =COUNTIF(Q4_Competitors!$B$5:$B$19,A7) -> 3 | C7: =MIN(Q4_Competitors!G11:G13) -> 24.85 | D7: =MEDIAN(Q4_Competitors!G11:G13) -> 64.85 | E7: =MAX(Q4_Competitors!G11:G13) -> 114.85 | F7: =AVERAGEIF(Q4_Competitors!$B$5:$B$19,A7,Q4_Competitors!$G$5:$G$19) -> 68.183333 | G7: =IFERROR(AVERAGEIF(Q4_Competitors!$B$5:$B$19,A7,Q4_Competitors!$M$5:$M$19),"n/a") -> 4 | H7: =SUMIF(Q4_Competitors!$B$5:$B$19,A7,Q4_Competitors!$N$5:$N$19) -> 2 | I7: =COUNTIFS(Q4_Competitors!$B$5:$B$19,A7,Q4_Competitors!$K$5:$K$19,">0") -> 2 | J7: =SUMIF(Q4_Competitors!$B$5:$B$19,A7,Q4_Competitors!$R$5:$R$19)/SUMIF(Q4_Competitors!$B$5:$B$19,A7,Q4_Competitors!$N$5:$N$19) -> 4
A8: Kogan | B8: =COUNTIF(Q4_Competitors!$B$5:$B$19,A8) -> 3 | C8: =MIN(Q4_Competitors!G14:G16) -> 83.99 | D8: =MEDIAN(Q4_Competitors!G14:G16) -> 139 | E8: =MAX(Q4_Competitors!G14:G16) -> 169 | F8: =AVERAGEIF(Q4_Competitors!$B$5:$B$19,A8,Q4_Competitors!$G$5:$G$19) -> 130.66333 | G8: =IFERROR(AVERAGEIF(Q4_Competitors!$B$5:$B$19,A8,Q4_Competitors!$M$5:$M$19),"n/a") -> 4 | H8: =SUMIF(Q4_Competitors!$B$5:$B$19,A8,Q4_Competitors!$N$5:$N$19) -> 141 | I8: =COUNTIFS(Q4_Competitors!$B$5:$B$19,A8,Q4_Competitors!$K$5:$K$19,">0") -> 3 | J8: =SUMIF(Q4_Competitors!$B$5:$B$19,A8,Q4_Competitors!$R$5:$R$19)/SUMIF(Q4_Competitors!$B$5:$B$19,A8,Q4_Competitors!$N$5:$N$19) -> 4.2446809
A9: Temple & Webster | B9: =COUNTIF(Q4_Competitors!$B$5:$B$19,A9) -> 3 | C9: =MIN(Q4_Competitors!G17:G19) -> 99.95 | D9: =MEDIAN(Q4_Competitors!G17:G19) -> 179 | E9: =MAX(Q4_Competitors!G17:G19) -> 219 | F9: =AVERAGEIF(Q4_Competitors!$B$5:$B$19,A9,Q4_Competitors!$G$5:$G$19) -> 165.98333 | G9: =IFERROR(AVERAGEIF(Q4_Competitors!$B$5:$B$19,A9,Q4_Competitors!$M$5:$M$19),"n/a") -> 4.6 | H9: =SUMIF(Q4_Competitors!$B$5:$B$19,A9,Q4_Competitors!$N$5:$N$19) -> 673 | I9: =COUNTIFS(Q4_Competitors!$B$5:$B$19,A9,Q4_Competitors!$K$5:$K$19,">0") -> 0 | J9: =SUMIF(Q4_Competitors!$B$5:$B$19,A9,Q4_Competitors!$R$5:$R$19)/SUMIF(Q4_Competitors!$B$5:$B$19,A9,Q4_Competitors!$N$5:$N$19) -> 4.5665676
A10: All 15 records | B10: =SUM(B5:B9) -> 15 | C10: =MIN(Q4_Competitors!$G$5:$G$19) -> 24.85 | D10: =MEDIAN(Q4_Competitors!$G$5:$G$19) -> 114.85 | E10: =MAX(Q4_Competitors!$G$5:$G$19) -> 219 | F10: =AVERAGE(Q4_Competitors!$G$5:$G$19) -> 118.51333 | G10: =AVERAGE(Q4_Competitors!$M$5:$M$19) -> 4.225 | H10: =SUM(H5:H9) -> 921 | I10: =SUM(I5:I9) -> 5 | J10: =SUM(Q4_Competitors!$R$5:$R$19)/SUM(Q4_Competitors!$N$5:$N$19) -> 4.4364821
A12: Like-for-like: MESH ergonomic chairs only
A13: Competitor | B13: Product ID | C13: Price | D13: Rating | E13: Reviews
A14: =INDEX(Q4_Competitors!$B$5:$B$19,MATCH(B14,Q4_Competitors!$A$5:$A$19,0)) -> Big W | B14: BW1 | C14: =INDEX(Q4_Competitors!$G$5:$G$19,MATCH(B14,Q4_Competitors!$A$5:$A$19,0)) -> 24.85 | D14: =INDEX(Q4_Competitors!$M$5:$M$19,MATCH(B14,Q4_Competitors!$A$5:$A$19,0)) -> 3 | E14: =INDEX(Q4_Competitors!$N$5:$N$19,MATCH(B14,Q4_Competitors!$A$5:$A$19,0)) -> 1
A15: =INDEX(Q4_Competitors!$B$5:$B$19,MATCH(B15,Q4_Competitors!$A$5:$A$19,0)) -> Bunnings | B15: BN1 | C15: =INDEX(Q4_Competitors!$G$5:$G$19,MATCH(B15,Q4_Competitors!$A$5:$A$19,0)) -> 59.85 | D15: =INDEX(Q4_Competitors!$M$5:$M$19,MATCH(B15,Q4_Competitors!$A$5:$A$19,0)) -> 2.9 | E15: =INDEX(Q4_Competitors!$N$5:$N$19,MATCH(B15,Q4_Competitors!$A$5:$A$19,0)) -> 27
A16: =INDEX(Q4_Competitors!$B$5:$B$19,MATCH(B16,Q4_Competitors!$A$5:$A$19,0)) -> Big W | B16: BW3 | C16: =INDEX(Q4_Competitors!$G$5:$G$19,MATCH(B16,Q4_Competitors!$A$5:$A$19,0)) -> 64.85 | D16: =INDEX(Q4_Competitors!$M$5:$M$19,MATCH(B16,Q4_Competitors!$A$5:$A$19,0)) -> no rating | E16: =INDEX(Q4_Competitors!$N$5:$N$19,MATCH(B16,Q4_Competitors!$A$5:$A$19,0)) -> 0
A17: =INDEX(Q4_Competitors!$B$5:$B$19,MATCH(B17,Q4_Competitors!$A$5:$A$19,0)) -> Kmart | B17: KM3 | C17: =INDEX(Q4_Competitors!$G$5:$G$19,MATCH(B17,Q4_Competitors!$A$5:$A$19,0)) -> 79.85 | D17: =INDEX(Q4_Competitors!$M$5:$M$19,MATCH(B17,Q4_Competitors!$A$5:$A$19,0)) -> 5 | E17: =INDEX(Q4_Competitors!$N$5:$N$19,MATCH(B17,Q4_Competitors!$A$5:$A$19,0)) -> 1
A18: =INDEX(Q4_Competitors!$B$5:$B$19,MATCH(B18,Q4_Competitors!$A$5:$A$19,0)) -> Kogan | B18: KG3 | C18: =INDEX(Q4_Competitors!$G$5:$G$19,MATCH(B18,Q4_Competitors!$A$5:$A$19,0)) -> 83.99 | D18: =INDEX(Q4_Competitors!$M$5:$M$19,MATCH(B18,Q4_Competitors!$A$5:$A$19,0)) -> no rating | E18: =INDEX(Q4_Competitors!$N$5:$N$19,MATCH(B18,Q4_Competitors!$A$5:$A$19,0)) -> 0
A19: =INDEX(Q4_Competitors!$B$5:$B$19,MATCH(B19,Q4_Competitors!$A$5:$A$19,0)) -> Temple & Webster | B19: TW2 | C19: =INDEX(Q4_Competitors!$G$5:$G$19,MATCH(B19,Q4_Competitors!$A$5:$A$19,0)) -> 99.95 | D19: =INDEX(Q4_Competitors!$M$5:$M$19,MATCH(B19,Q4_Competitors!$A$5:$A$19,0)) -> 4.4 | E19: =INDEX(Q4_Competitors!$N$5:$N$19,MATCH(B19,Q4_Competitors!$A$5:$A$19,0)) -> 284
A20: =INDEX(Q4_Competitors!$B$5:$B$19,MATCH(B20,Q4_Competitors!$A$5:$A$19,0)) -> Kogan | B20: KG1 | C20: =INDEX(Q4_Competitors!$G$5:$G$19,MATCH(B20,Q4_Competitors!$A$5:$A$19,0)) -> 169 | D20: =INDEX(Q4_Competitors!$M$5:$M$19,MATCH(B20,Q4_Competitors!$A$5:$A$19,0)) -> 4.3 | E20: =INDEX(Q4_Competitors!$N$5:$N$19,MATCH(B20,Q4_Competitors!$A$5:$A$19,0)) -> 128
A21: Mesh chairs: lowest / median / highest | C21: =MIN(C14:C20) -> 24.85 | D21: =MEDIAN(C14:C20) -> 79.85 | E21: =MAX(C14:C20) -> 169
A22: (row 21: C = lowest, D = median, E = highest mesh-chair price)
A24: Discount behaviour (items with a 'was' price)
A25: Metric | B25: Value
A26: Average discount % where an original price is shown | B26: =AVERAGEIF(Q4_Competitors!$K$5:$K$19,">0") -> 0.37200362
A27: Largest discount % | B27: =MAX(Q4_Competitors!$K$5:$K$19) -> 0.51575931
A28: Items with no discount shown (of 15) | B28: =COUNTIF(Q4_Competitors!$K$5:$K$19,0) -> 10
A29: Kogan avg discount % vs SRP (3 items) | B29: =AVERAGE(Q4_Competitors!K14:K16) -> 0.48585205
A30: Big W avg discount % (3 items, 1 has none) | B30: =AVERAGE(Q4_Competitors!K11:K13) -> 0.13415398
A32: Kogan member saving vs non-member price (avg $) | B32: =AVERAGE(Q4_Competitors!G14-Q4_Competitors!H14,Q4_Competitors!G15-Q4_Competitors!H15,Q4_Competitors!G16-Q4_Competitors!H16) -> 25.67

Sheet Q5_Opportunities
A1: Q5 - Product opportunities for During Days (Australia)
A2: Observed evidence = seen on a source page on 8 Oct 2026. Analyst inference = my judgement. Selling prices are inference, not supplier-based.
A4: Item | B4: 1. Galvanised steel raised garden bed | C4: 2. Cat tree / scratching tower (flat-pack) | D4: 3. Lockable outdoor storage box (resin)
A5: Category | B5: Garden / outdoor structures | C5: Pet furniture (new adjacent category) | D5: Outdoor storage
A6: Current market price range (verified examples) | B6: $69 (Bunnings Jack 160x80cm) to $84.95 (T&W Gordo, from $84.95; its page shows a $84.95-$124 range across options) | C6: $42.85 (Kogan Beastie 104cm) to $150.99 (Kogan PaWz 138cm); Bunnings Alopet 142cm $82.43; Kmart Advwin 84cm $44.90 | D6: $59 (Keter 113L) to $339 (Keter 570L); mainstream 290L at $77-$82 (Bunnings marketplace, Kogan); Keter 350L $179
A7: Approx. selling price today (median of verified examples below) | B7: =D32 -> 76.975 | C7: =D33 -> 63.665 | D7: =D34 -> 130.475
A8: Potential During Days selling price (inference) | B8: $89-$129 for 240cm / taller or modular beds | C8: $79-$99 for 120-145cm 'furniture-style' towers | D8: $119-$149 for 330-390L with gas struts / wheels
A9: Why selected | B9: Strong seasonal pull (spring peak in Google Trends), sells across Bunnings, T&W and Kogan, easy to differentiate by size/height/bundle, review volume on T&W is high (217 reviews). | C9: Highest and rising search interest of the three (Google Trends 5-yr average about 52 vs 29 and 21), fast-growing online pet spend, sits near During Days' furniture skills; very wide price spread shows room for a design-led mid-price range. | D9: Proven demand on trusted brands (Keter 350L: 61 reviews; 570L: 140; Lifetime 567L: 350 reviews at Bunnings), adjacent to garden/outdoor range, lockable/weatherproof features are easy to explain.
A10: Evidence of demand - OBSERVED | B10: Google Trends AU, 5 yrs: 'raised garden bed' average index about 29 (relative), clear spring peaks. Australia Post: Home & Garden online spend $9.9b in 2025 (+9.9%), 5.1m households. T&W Gordo 4.6 stars (217 reviews); Bunnings Jack 4.0 (24). | C10: Google Trends AU, 5 yrs: 'cat tree' average index about 52 (highest of three) with recent peaks near 100. Australia Post: Pet products online spend $1.4b in 2025 (+15.2%), 1.2m households, 37% of category spend online. Listed by Kogan (several), Bunnings marketplace and Kmart marketplace. | D10: Bunnings category page carries 100s of reviews on Keter/Lifetime lines (see table below). Google Trends 'outdoor storage box' is the lowest of the three (average about 21). Kogan Gardeon 290L has 24 reviews at 4.0.
A11: Evidence - ANALYST INFERENCE | B11: Demand is seasonal (Aug-Nov peak), so launch stock must land before September. Buyers compare on size and steel thickness. | C11: Review volume on verified listings is low (0-5), so search interest may not yet translate to many sales per listing; treat as a test range. Quality/stability claims will matter. | D11: Price pressure from 290L boxes at ~$77-82 means During Days should avoid the 290L tier and compete on bigger/better-featured boxes.
A12: Major competitors | B12: Bunnings, Temple & Webster (Living Fusion), Kogan marketplace sellers, Amazon AU sellers | C12: Kogan (PaWz, Beastie), Bunnings and Kmart marketplace sellers, Amazon AU | D12: Bunnings (Keter, Lifetime), Kogan (Gardeon), Big W / Bunnings marketplace, Amazon AU
A13: Key risk / limitation | B13: Commodity pricing, thin-steel quality complaints, bulky cartons raise courier cost, seasonal. | C13: New customer segment (pets), stability/return risk, low verified review depth. | D13: Bulky freight cost, UV warping complaints, Keter brand trust at Bunnings.
A15: Verified competitor examples (read from the product/category page on 8 Oct 2026)
A16: Product idea | B16: Retailer / item | C16: Price ($) | D16: Was / ref price ($) | E16: Rating | F16: Reviews | G16: URL
A17: Raised bed | B17: Bunnings - Jack 1600 x 800mm Rectangular Raised Garden Bed | C17: 69 | D17: none shown | E17: 4 | F17: 24 | G17: https://www.bunnings.com.au/jack-1600-x-800mm-rectangular-raised-garden-bed_p0807491
A18: Raised bed | B18: Temple & Webster - Living Fusion Gordo Galvanised Steel Raised Garden Bed (from $84.95; page shows a $84.95-$124 range across size/colour options, not a was-price) | C18: 84.95 | D18: none shown | E18: 4.6 | F18: 217 | G18: https://www.templeandwebster.com.au/Gordo-Galvanised-Steel-Raised-Garden-Bed-OIKT1274.html
A19: Cat tree | B19: Kogan - PaWz Wooden Cat Tree with Condo 138cm (non-member; member $128.99) | C19: 150.99 | D19: 251.99 | E19: no rating | F19: 0 | G19: https://www.kogan.com/au/buy/sel-pawz-cat-tree-scratching-post-scratcher-cats-tower-wood-condo-toys-house-138cm-pt1155/
A20: Cat tree | B20: Kogan - BEASTIE Cat Tree Tower 104cm (non-member; member $39.75) | C20: 42.85 | D20: 199.85 | E20: no rating | F20: 0 | G20: https://www.kogan.com/au/buy/aussie-union-group-beastie-cat-tree-tower-scratching-post-black-104cm-kgv_a-cat-e-4st-104-bk/
A21: Cat tree | B21: Bunnings marketplace - Alopet 142cm Cat Tree Tower | C21: 82.43 | D21: none shown | E21: 3.6 | F21: 5 | G21: https://www.bunnings.com.au/alopet-142cm-cat-tree-tower-scratching-post-scratcher_p0520575
A22: Cat tree | B22: Kmart marketplace - Advwin Cat Scratching Post Cat Tree | C22: 44.9 | D22: none shown | E22: no rating | F22: 0 | G22: https://www.kmart.com.au/product/advwin-cat-scratching-post-cat-tree-110009500/
A23: Storage box | B23: Kogan - Gardeon Outdoor Storage Box 290L Lockable (non-member; member $79.41) | C23: 81.95 | D23: 104.99 | E23: 4 | F23: 24 | G23: https://www.kogan.com/au/buy/290l-plastic-outdoor-storage-box-container-weatherproof-black-home-furniture/
A24: Storage box | B24: Bunnings - Keter 113L Graphite City Outdoor Storage Box | C24: 59 | D24: none shown | E24: 4.8 | F24: 38 | G24: https://www.bunnings.com.au/products/outdoor-living/outdoor-furniture/outdoor-storage/outdoor-storage-boxes
A25: Storage box | B25: Bunnings - Keter 350L Kentwood Storage Box | C25: 179 | D25: none shown | E25: 4.7 | F25: 61 | G25: https://www.bunnings.com.au/products/outdoor-living/outdoor-furniture/outdoor-storage/outdoor-storage-boxes
A26: Storage box | B26: Bunnings - Keter 570L Rockwood Storage Box | C26: 339 | D26: none shown | E26: 4.7 | F26: 140 | G26: https://www.bunnings.com.au/products/outdoor-living/outdoor-furniture/outdoor-storage/outdoor-storage-boxes
A27: Storage box | B27: Bunnings - Lifetime 567L Tirari Storage Box | C27: 255 | D27: none shown | E27: 4.4 | F27: 350 | G27: https://www.bunnings.com.au/products/outdoor-living/outdoor-furniture/outdoor-storage/outdoor-storage-boxes
A28: Storage box | B28: Bunnings marketplace - Relaxio 290L Lockable Organiser (delivery included) | C28: 77.16 | D28: none shown | E28: no rating | F28: 0 | G28: https://www.bunnings.com.au/products/outdoor-living/outdoor-furniture/outdoor-storage/outdoor-storage-boxes
A30: Price check from the verified examples (formulas)
A31: Product idea | B31: Lowest verified price | C31: Highest verified price | D31: Median verified price
A32: Raised bed | B32: =_xlfn.MINIFS($C$17:$C$28,$A$17:$A$28,A32) -> 69 | C32: =_xlfn.MAXIFS($C$17:$C$28,$A$17:$A$28,A32) -> 84.95 | D32: =MEDIAN(C17:C18) -> 76.975
A33: Cat tree | B33: =_xlfn.MINIFS($C$17:$C$28,$A$17:$A$28,A33) -> 42.85 | C33: =_xlfn.MAXIFS($C$17:$C$28,$A$17:$A$28,A33) -> 150.99 | D33: =MEDIAN(C19:C22) -> 63.665
A34: Storage box | B34: =_xlfn.MINIFS($C$17:$C$28,$A$17:$A$28,A34) -> 59 | C34: =_xlfn.MAXIFS($C$17:$C$28,$A$17:$A$28,A34) -> 339 | D34: =MEDIAN(C23:C28) -> 130.475
A37: Break-even buying-cost calculator (no supplier quotes were available - assumptions in blue, replace with real quotes)
A38: Assumption | B38: Value | C38: Note
A39: Payment/transaction fee % | B39: 0.03 | C39: Same 3% as Q6
A40: Marketing cost per order ($) | B40: 10 | C40: Same $10 as Q6
A41: Outbound shipping per order ($) | B41: 15 | C41: ASSUMPTION for bulky flat-pack items; Q6's $8 was for a smaller item. Replace with a courier quote.
A42: Target net margin % | B42: 0.15 | C42: Analyst target, not given in the assessment
A44: Product | B44: Assumed selling price ($) | C44: Max landed cost per unit that still gives target margin ($) | D44: Net profit per unit at that cost ($)
A45: Raised garden bed | B45: 99 | C45: =B45*(1-$B$39-$B$42)-$B$41-$B$40 -> 56.18 | D45: =B45*(1-$B$39)-C45-$B$41-$B$40 -> 14.85
A46: Cat tree | B46: 89 | C46: =B46*(1-$B$39-$B$42)-$B$41-$B$40 -> 47.98 | D46: =B46*(1-$B$39)-C46-$B$41-$B$40 -> 13.35
...

Sheet Q6_Profitability
A1: Q6 - Competitor price analysis
A2: Inputs from the assessment (blue). Everything else is a formula.
A4: Input | B4: Value
A5: Selling price ($) | B5: 149.95
A6: Product cost ($) | B6: 110
A7: Payment / transaction cost % | B7: 0.03
A8: Shipping cost per order ($) | B8: 8
A9: Marketing cost per order ($) | B9: 10
A11: Result | B11: Value | C11: How calculated
A12: 1. Gross dollar profit (before other costs) | B12: =B5-B6 -> 39.95 | C12: Selling price - product cost
A13: 2. Gross profit margin | B13: =B12/B5 -> 0.26642214 | C13: Gross profit / selling price
A14: Payment / transaction cost ($) | B14: =B5*B7 -> 4.4985 | C14: 3% x selling price
A15: Shipping ($) | B15: =B8 -> 8 | C15: Given
A16: Marketing allocation ($) | B16: =B9 -> 10 | C16: Given
A17: Total listed costs ($) | B17: =SUM(B14:B16) -> 22.4985 | C17: Payment + shipping + marketing
A18: 3. Profit after listed costs ($) | B18: =B12-B17 -> 17.4515 | C18: Gross profit - listed costs
A19: 4. Net margin after listed costs | B19: =B18/B5 -> 0.11638213 | C19: Profit after costs / selling price
A21: Independent check (different route)
A22: Profit = price x (1 - 3%) - cost - shipping - marketing | B22: =B5*(1-B7)-B6-B8-B9 -> 17.4515 | C22: =IF(ABS(B22-B18)<0.005,"MATCHES row 18","MISMATCH") -> MATCHES row 18
A24: Break-even and target prices
A25: Question | B25: Value | C25: How calculated
A26: Price where profit after listed costs = $0 | B26: =(B6+B8+B9)/(1-B7) -> 131.95876 | C26: (cost + shipping + marketing) / (1 - payment %)
A27: Target net margin | B27: 0.15 | C27: Analyst assumption (not in the assessment)
A28: Price needed to hit the target net margin | B28: =(B6+B8+B9)/(1-B7-B27) -> 156.09756 | C28: (cost + shipping + marketing) / (1 - payment % - target margin)
A29: Product cost needed to hit target at $149.95 | B29: =B5*(1-B7-B27)-B8-B9 -> 104.959 | C29: Price x (1 - payment % - target) - shipping - marketing
A31: Price scenarios
A32: Selling price ($) | B32: Profit after costs ($) | C32: Net margin
A33: 139.95 | B33: =A33*(1-$B$7)-$B$6-$B$8-$B$9 -> 7.7515 | C33: =B33/A33 -> 0.055387638
A34: 149.95 | B34: =A34*(1-$B$7)-$B$6-$B$8-$B$9 -> 17.4515 | C34: =B34/A34 -> 0.11638213
A35: 154.95 | B35: =A35*(1-$B$7)-$B$6-$B$8-$B$9 -> 22.3015 | C35: =B35/A35 -> 0.14392707
A36: 159.95 | B36: =A36*(1-$B$7)-$B$6-$B$8-$B$9 -> 27.1515 | C36: =B36/A36 -> 0.16974992
A37: 164.95 | B37: =A37*(1-$B$7)-$B$6-$B$8-$B$9 -> 32.0015 | C37: =B37/A37 -> 0.19400727
A38: 169.95 | B38: =A38*(1-$B$7)-$B$6-$B$8-$B$9 -> 36.8515 | C38: =B38/A38 -> 0.21683731
A40: GST sensitivity (assumption)
A41: GST rate | B41: 0.1 | C41: Australian retail prices are normally GST-inclusive. The assessment does not say, so the main answer ignores GST.
A42: Profit after listed costs if $149.95 includes GST ($) | B42: =B5/(1+B41)-B6-B5*B7-B8-B9 -> 3.8196818 | C42: Assumes the $110 cost and the other costs are GST-free amounts. If true, the product is close to break-even.
A43: Net margin on GST-exclusive revenue | B43: =B42/(B5/(1+B41)) -> 0.02802034

Sheet Q8_Sales
A1: Q8 - Data investigation: monthly sales
A2: Inputs from the assessment (blue). Derived columns are formulas.
A4: Month | B4: Visitors | C4: Orders | D4: Sales ($) | E4: Conversion rate | F4: Average order value ($) | G4: Revenue per visitor ($) | H4: Visitors MoM % | I4: Orders MoM % | J4: Sales MoM % | K4: Conv. rate change (pts)
A5: January | B5: 10000 | C5: 200 | D5: 30000 | E5: =C5/B5 -> 0.02 | F5: =D5/C5 -> 150 | G5: =D5/B5 -> 3 | H5: - | I5: - | J5: - | K5: -
A6: February | B6: 12000 | C6: 210 | D6: 31500 | E6: =C6/B6 -> 0.0175 | F6: =D6/C6 -> 150 | G6: =D6/B6 -> 2.625 | H6: =B6/B5-1 -> 0.2 | I6: =C6/C5-1 -> 0.05 | J6: =D6/D5-1 -> 0.05 | K6: =(E6-E5)*100 -> -0.25
A7: March | B7: 15000 | C7: 205 | D7: 30750 | E7: =C7/B7 -> 0.013666667 | F7: =D7/C7 -> 150 | G7: =D7/B7 -> 2.05 | H7: =B7/B6-1 -> 0.25 | I7: =C7/C6-1 -> -0.023809524 | J7: =D7/D6-1 -> -0.023809524 | K7: =(E7-E6)*100 -> -0.38333333
A8: April | B8: 20000 | C8: 210 | D8: 31500 | E8: =C8/B8 -> 0.0105 | F8: =D8/C8 -> 150 | G8: =D8/B8 -> 1.575 | H8: =B8/B7-1 -> 0.33333333 | I8: =C8/C7-1 -> 0.024390244 | J8: =D8/D7-1 -> 0.024390244 | K8: =(E8-E7)*100 -> -0.31666667
A10: Jan -> Apr change | B10: =B8/B5-1 -> 1 | C10: =C8/C5-1 -> 0.05 | D10: =D8/D5-1 -> 0.05 | E10: =E8/E5-1 -> -0.475 | F10: =F8/F5-1 -> 0 | G10: =G8/G5-1 -> -0.475
A11: Jan -> Apr absolute change | B11: =B8-B5 -> 10000 | C11: =C8-C5 -> 10 | D11: =D8-D5 -> 1500 | E11: =(E8-E5)*100 -> -0.95
A13: Incremental view (Jan -> Apr)
A14: Extra visitors | B14: =B8-B5 -> 10000
A15: Extra orders | B15: =C8-C5 -> 10
A16: Extra visitors needed per extra order | B16: =B14/B15 -> 1000
A17: Conversion of the extra visitors only | B17: =B15/B14 -> 0.001
A18: Orders April would have if Jan's conversion held | B18: =B8*E5 -> 400
A19: Orders 'missing' vs Jan conversion | B19: =B18-C8 -> 190
A20: Value of those missing orders at April AOV ($) | B20: =B19*F8 -> 28500
A22: What the data shows: traffic doubled (+100%), orders and sales rose only 5%, conversion fell from 2.00% to 1.05%, and average order value stayed at exactly $150 every month. The extra traffic is not buying.
A23: What might explain it (needs more data): lower-quality traffic from a new/paid channel, a site or checkout problem, stock-outs, or changed pricing/promotions.

Sheet Q9_Funnel
A1: Q9 - Funnel analysis
A2: Counts from the assessment (blue). Rates are formulas.
A4: Stage | B4: Count
A5: Website visits | B5: 10000
A6: Product-page views | B6: 500
A7: Add-to-carts | B7: 100
A8: Purchases | B8: 20
A10: Conversion | B10: Numerator | C10: Denominator | D10: Rate | E10: Drop-off % | F10: People lost
A11: 1. Visit -> Product page | B11: =B6 -> 500 | C11: =B5 -> 10000 | D11: =B11/C11 -> 0.05 | E11: =1-D11 -> 0.95 | F11: =C11-B11 -> 9500
A12: 2. Product page -> Add to cart | B12: =B7 -> 100 | C12: =B6 -> 500 | D12: =B12/C12 -> 0.2 | E12: =1-D12 -> 0.8 | F12: =C12-B12 -> 400
A13: 3. Add to cart -> Purchase | B13: =B8 -> 20 | C13: =B7 -> 100 | D13: =B13/C13 -> 0.2 | E13: =1-D13 -> 0.8 | F13: =C13-B13 -> 80
A14: 4. Visit -> Purchase (overall) | B14: =B8 -> 20 | C14: =B5 -> 10000 | D14: =B14/C14 -> 0.002 | E14: =1-D14 -> 0.998 | F14: =C14-B14 -> 9980
A16: Weakest stage (lowest rate among stages 1-3) | B16: =INDEX(A11:A13,MATCH(MIN(D11:D13),D11:D13,0)) -> 1. Visit -> Product page
A17: Check: product of the three stage rates equals overall rate | B17: =IF(ABS(D11*D12*D13-D14)<0.0000001,"OK","MISMATCH") -> OK
A19: Overall conversion (0.20%) is not the same thing as a stage conversion: it is the product of all three stages (5% x 20% x 20%).

Sheet Sources
A1: Source register
A2: All accessed 8 Oct 2026 unless stated. 'Opened' = read on the live page by me; 'Fetched' = read via the page-fetch tool.
A3: Evidence class: PRIMARY = read on the original page or official report. SECONDARY = a third party reporting someone else's figure. No figure in the answers rests on a search snippet alone. Potential selling prices and risk statements in Q5 are analyst INFERENCE and are labelled as such in the answers.
A4: Source ID | B4: Question | C4: Competitor / item | D4: Claim / data point | E4: URL | F4: Source type | G4: Access date | H4: Notes | I4: Evidence class
A5: S01 | B5: Q4 | C5: Kmart - Boucle Home Office Chair | D5: Price 149; rating 4.7; reviews 12 | E5: https://www.kmart.com.au/product/boucle-home-office-chair-43228386/ | F5: Retailer product page (opened in Chrome) | G5: 46303 | I5: PRIMARY
A6: S02 | B6: Q4 | C6: Kmart - Sky Office Chair | D6: Price 149; rating None; reviews 0 | E6: https://www.kmart.com.au/product/sky-office-chair-43682737/ | F6: Retailer product page (opened in Chrome) | G6: 46303 | I6: PRIMARY
A7: S03 | B7: Q4 | C7: Kmart - Alfordson Mesh Office Chair Executive Seat Tilt Gaming Racin | D7: Price 79.85; rating 5.0; reviews 1 | E7: https://www.kmart.com.au/product/alfordson-mesh-office-chair-executive-seat-tilt-gaming-racing-computer-grey-110049597/ | F7: Retailer product page (opened in Chrome) | G7: 46303 | I7: PRIMARY
A8: S04 | B8: Q4 | C8: Bunnings - ALFORDSON Mesh Office Chair Dark Grey | D8: Price 59.85; rating 2.9; reviews 27 | E8: https://www.bunnings.com.au/alfordson-mesh-office-chair-dark-grey_p0508818 | F8: Retailer product page (opened in Chrome) | G8: 46303 | I8: PRIMARY
A9: S05 | B9: Q4 | C9: Bunnings - ALFORDSON Office Chair White | D9: Price 109.85; rating 3.9; reviews 39 | E9: https://www.bunnings.com.au/alfordson-office-chair-white_p0477986 | F9: Retailer product page (opened in Chrome) | G9: 46303 | I9: PRIMARY
A10: S06 | B10: Q4 | C10: Bunnings - Artiss Black PU Leather Executive Office Chair | D10: Price 135.66; rating 4.4; reviews 26 | E10: https://www.bunnings.com.au/artiss-black-pu-leather-executive-office-chair_p0215110 | F10: Retailer product page (opened in Chrome) | G10: 46303 | I10: PRIMARY
A11: S07 | B11: Q4 | C11: Big W - 1 ALFORDSON Office Chair (Mesh, Conrad series) | D11: Price 24.85; rating 3.0; reviews 1 | E11: https://www.bigw.com.au/product/1-alfordson-office-chair/p/9900120141 | F11: Retailer product page (opened in Chrome) | G11: 46303 | I11: PRIMARY
A12: S08 | B12: Q4 | C12: Big W - ALFORDSON Velvet Office Chair for Work Mid Back Grey | D12: Price 114.85; rating 5.0; reviews 1 | E12: https://www.bigw.com.au/product/alfordson-velvet-office-chair-for-work-mid-back-grey/p/9900116761 | F12: Retailer product page (opened in Chrome) | G12: 46303 | I12: PRIMARY
A13: S09 | B13: Q4 | C13: Big W - ALFORDSON Mesh Office Chair Racing Ergonomic Computer Chair | D13: Price 64.85; rating None; reviews 0 | E13: https://www.bigw.com.au/product/alfordson-mesh-office-chair-racing-ergonomic-computer-chair-all-black/p/9902748573 | F13: Retailer product page (opened in Chrome) | G13: 46303 | I13: PRIMARY
A14: S10 | B14: Q4 | C14: Kogan - Ergolux Plus Ergonomic Mesh Office Chair with Footrest (Blac | D14: Price 169; rating 4.3; reviews 128 | E14: https://www.kogan.com/au/buy/ergolux-plus-ergonomic-mesh-office-chair-with-footrest-black-ergolux/ | F14: Retailer product page (opened in Chrome) | G14: 46303 | I14: PRIMARY
A15: S11 | B15: Q4 | C15: Kogan - Ergolux Core Ergonomic Foam Office Chair (Black) | D15: Price 139; rating 3.7; reviews 13 | E15: https://www.kogan.com/au/buy/ergolux-core-ergonomic-foam-office-chair-black-ergolux/ | F15: Retailer product page (opened in Chrome) | G15: 46303 | I15: PRIMARY
A16: S12 | B16: Q4 | C16: Kogan - Levede Adjustable Armrest Office Mesh Gaming Chair Recliner | D16: Price 83.99; rating None; reviews 0 | E16: https://www.kogan.com/au/buy/sel-levede-office-chair-mesh-gaming-executive-tilt-chairs-computer-study-work-seat-of1040-bk/ | F16: Retailer product page (opened in Chrome) | G16: 46303 | I16: PRIMARY
... A36: S32 | B36: Q5 | C36: Bunnings marketplace - Relaxio 290L Lockable Organiser (delivery included) | D36: Price $77.16 | E36: https://www.bunnings.com.au/products/outdoor-living/outdoor-furniture/outdoor-storage/outdoor-storage-boxes | F36: Retailer product/category page (opened in Chrome) | G36: 46303 | I36: PRIMARY
A37: S33 | B37: Q5 | C37: Google Trends AU | D37: 5-year comparison: raised garden bed vs outdoor storage box vs cat tree (relative index; averages about 29 / 21 / 52 read from the chart) | E37: https://trends.google.com/trends/explore?date=today%205-y&geo=AU&q=raised%20garden%20bed,outdoor%20storage%20box,cat%20tree&hl=en-AU | F37: Google Trends (opened in Chrome) | G37: 46303 | H37: Averages read visually from the chart; Trends shows relative search interest, not sales. | I37: PRIMARY
A38: S34 | B38: Q5/Q7 | C38: Australia Post - Home & Garden | D38: $9.9b online in 2025, +9.9% YoY; 5.1m households; $286.77 basket; 26% of category spend online; 36% of sale-waiters hold out for H&G discounts | E38: https://auspost.com.au/content/dam/auspost_corp/media/documents/australia-post-ecommerce-report-2026-home-garden.pdf | F38: Official industry report (fetched) | G38: 46303 | H38: Three press/industry-blog articles (S35-S37) quote $11.4b for Home & Garden and attribute it to the main report. Not reconciled, so the $9.9b read in this PDF is used and the conflict is stated in the answers. The PDF itself credits CommBank iQ and points to p.38 of the main report, which was not opened. | I38: PRIMARY
A39: S35 | B39: Q5/Q7 | C39: Press: Parcel & Postal Technology International | D39: Quotes Home & Garden online spend A$11.4bn (2025) from the Australia Post report; Fashion A$11.6bn | E39: https://www.parcelandpostaltechnologyinternational.com/news/e-commerce/australian-online-spending-reaches-a82-6bn-in-2025.html | F39: Trade press article (fetched) | G39: 46303 | H39: Secondary source; conflicts with the $9.9b in the category PDF (S34). | I39: SECONDARY
A40: S36 | B40: Q5/Q7 | C40: Press: IPC (International Post Corporation) | D40: Quotes Home and Garden $11.4 billion; Online Marketplaces $18.9b; Fashion $11.6b | E40: https://www.ipc.be/news-portal/e-commerce/2026/03/18/16/03/aussies-add-82-6-billion-to-cart | F40: Trade press article (fetched) | G40: 46303 | H40: Secondary source; conflicts with S34. | I40: SECONDARY
A41: S37 | B41: Q5/Q7 | C41: Blog: eightx.co | D41: Lists Home & Garden $11.4B, +10.5% YoY, citing the Australia Post 2026 report | E41: https://eightx.co/blog/australian-online-retail-category-share-2026 | F41: Industry blog (fetched) | G41: 46303 | H41: Secondary source; weakest of the three. Conflicts with S34 on both value and growth (+10.5% vs +9.9%). | I41: SECONDARY
A42: S38 | B42: Q5/Q7 | C42: Australia Post - Pet products | D42: $1.4b online in 2025, +15.2% YoY; 1.2m households; $120.62 basket; 37% of category spend online | E42: https://auspost.com.au/content/dam/auspost_corp/media/documents/australia-post-ecommerce-report-2026-pet-products.pdf | F42: Official industry report (fetched) | G42: 46303 | I42: PRIMARY
A43: S39 | B43: Q7 | C43: Australia Post eCommerce Report 2026 (landing page) | D43: Online spend $82.6b in 2025, +14% (2024: $72.5b); Home & Garden listed among top five categories, no category spend figure on this page | E43: https://auspost.com.au/business/ecommerce/ecommerce-report | F43: Official industry report page (fetched) | G43: 46303 | I43: PRIMARY
A44: S40 | B44: Q7 | C44: Australia Post eCommerce trends (FY26 Q4 update) | D44: Q4 FY26: $21.9b spent online, record-low $90 average basket, marketplaces 42% of transactions (+17% YoY) | E44: https://auspost.com.au/business/marketing-and-communications/access-data-and-insights/ecommerce-trends | F44: Official industry report page (fetched) | G44: 46303 | I44: PRIMARY
A45: S41 | B45: Q7/Q13 | C45: ABS household spending | D45: Household spending unchanged in Aug 2026, +6.8% YoY; furniture fell (released 29 Sep 2026) | E45: https://www.abs.gov.au/media-centre/media-releases/household-spending-unchanged-august | F45: Government statistics (fetched) | G45: 46303 | I45: PRIMARY
A46: S42 | B46: Q7/Q13 | C46: Amazon AU Best Sellers | D46: Live Best Sellers page for Home Storage & Organisation loads and shows category rankings | E46: https://www.amazon.com.au/gp/bestsellers/home/4975214051 | F46: Marketplace ranking page (opened in Chrome) | G46: 46303 | H46: Rank only; no unit sales published. | I46: PRIMARY
A47: S43 | B47: Q7 | C47: Kogan | D47: Office chair/garden/pet category pages with 'Don't Pay' reference prices and seller names | E47: https://www.kogan.com/au/c/garden-beds/ | F47: Retailer (opened in Chrome) | G47: 46303 | I47: PRIMARY
A48: S44 | B48: Q13 | C48: Kmart | D48: 'Bestseller' and 'Trending' badges on search results | E48: https://www.kmart.com.au/search/?searchTerm=office%20chair | F48: Retailer search page | G48: 46303 | H48: Badge criteria not published (e.g. a 0-review chair carried 'Bestseller'). | I48: PRIMARY

Sheet QA
A1: QA - automated cross-checks (all should read PASS)
A3: Check | B3: Result
A4: Q1: sum of profits = total sell - total cost | B4: =IF(SUM(Q1_Profit!D5:D9)=SUM(Q1_Profit!C5:C9)-SUM(Q1_Profit!B5:B9),"PASS","FAIL") -> PASS
A5: Q1: highest margin product is Bedside Table | B5: =IF(Q1_Profit!B11="Bedside Table","PASS","FAIL") -> PASS
A6: Q4: 15 records in total | B6: =IF(COUNTA(Q4_Competitors!A5:A19)=15,"PASS","FAIL") -> PASS
A7: Q4: at least 3 products per competitor (all five) | B7: =IF(MIN(Q4_Summary!B5:B9)>=3,"PASS","FAIL") -> PASS
A8: Q4: every record has a URL | B8: =IF(COUNTIF(Q4_Competitors!O5:O19,"https://*")=15,"PASS","FAIL") -> PASS
A9: Q4: every record has a price | B9: =IF(COUNT(Q4_Competitors!G5:G19)=15,"PASS","FAIL") -> PASS
A10: Q6: profit matches independent route | B10: =IF(Q6_Profitability!C22="MATCHES row 18","PASS","FAIL") -> PASS
A11: Q6: gross profit = 39.95 | B11: =IF(ROUND(Q6_Profitability!B12,2)=39.95,"PASS","FAIL") -> PASS
A12: Q8: AOV constant at $150 in all months | B12: =IF(AND(Q8_Sales!F5=150,Q8_Sales!F6=150,Q8_Sales!F7=150,Q8_Sales!F8=150),"PASS","FAIL") -> PASS
A13: Q9: stage rates multiply to overall rate | B13: =IF(Q9_Funnel!B17="OK","PASS","FAIL") -> PASS
A14: Sources: at least 30 rows registered | B14: =IF(COUNTA(Sources!A5:A200)>=30,"PASS","FAIL") -> PASS
A15: Q6: net profit rounds to 17.45 and net margin to 11.6% | B15: =IF(AND(ROUND(Q6_Profitability!B18,2)=17.45,ROUND(Q6_Profitability!B19,3)=0.116),"PASS","FAIL") -> PASS
A16: Q6: total listed costs = 22.50 (3% x 149.95 + 8 + 10) | B16: =IF(ROUND(Q6_Profitability!B17,2)=22.5,"PASS","FAIL") -> PASS
A17: Q8: conversion Jan-Apr = 2.00%, 1.75%, 1.37%, 1.05% (typed independently) | B17: =IF(AND(ROUND(Q8_Sales!E5,4)=0.02,ROUND(Q8_Sales!E6,4)=0.0175,ROUND(Q8_Sales!E7,4)=0.0137,ROUND(Q8_Sales!E8,4)=0.0105),"PASS","FAIL") -> PASS
A18: Q8: conversion recomputed from raw inputs (orders / visitors) matches column E | B18: =IF(ABS(Q8_Sales!E8-Q8_Sales!C8/Q8_Sales!B8)+ABS(Q8_Sales!E5-Q8_Sales!C5/Q8_Sales!B5)<0.0000001,"PASS","FAIL") -> PASS
A19: Q9: stage rates = 5%, 20%, 20% and overall 0.20% (typed independently) | B19: =IF(AND(ROUND(Q9_Funnel!D11,4)=0.05,ROUND(Q9_Funnel!D12,4)=0.2,ROUND(Q9_Funnel!D13,4)=0.2,ROUND(Q9_Funnel!D14,4)=0.002),"PASS","FAIL") -> PASS
A20: Q4: all 15 prices recompute the same median via a second route (SUMPRODUCT rank) | B20: =IF(COUNTIF(Q4_Competitors!G5:G19,"<"&Q4_Summary!D10)=7,"PASS","FAIL") -> PASS
A21: Q4: 15 distinct product IDs (no duplicated records) | B21: =IF(SUMPRODUCT(1/COUNTIF(Q4_Competitors!A5:A19,Q4_Competitors!A5:A19))=15,"PASS","FAIL") -> PASS
A22: Sources: every source row has an https URL | B22: =IF(COUNTIF(Sources!E5:E200,"https://*")=COUNTA(Sources!A5:A200),"PASS","FAIL") -> PASS
A24: Overall | B24: =IF(COUNTIF(B4:B22,"PASS")=19,"ALL PASS","REVIEW") -> ALL PASS
